<mujoco model="franka_skin">
  <compiler angle="radian" meshdir="assets"/>

  <option integrator="implicitfast"/>

  <default>
    <default class="fr3">
      <joint armature="0.1" damping="1"/>
      <position inheritrange="1"/>
      <default class="visual">
        <geom type="mesh" group="2" contype="0" conaffinity="0"/>
      </default>
      <default class="collision">
        <geom type="mesh" group="3" mass="0" density="0"/>
      </default>
      <site size="0.001" rgba="0.5 0.5 0.5 0.3" group="4"/>
    </default>

    <default class="panda">
      <material specular="0.5" shininess="0.25"/>
      <joint armature="0.1" damping="1" axis="0 0 1" range="-2.8973 2.8973"/>
      <general dyntype="none" biastype="affine" ctrlrange="-2.8973 2.8973" forcerange="-87 87"/>
    </default>

    <default class="skin_sensor_site">
      <site type="sphere" size="0.004" rgba="1 0.2 0.2 1" group="2"/>
    </default>

    <default class="skin">
      <geom group="2" contype="0" conaffinity="0" rgba="0.25 0.55 0.85 0.55" mass="0" density="0"/>
    </default>
  </default>

  <asset>
    <material name="black" rgba=".2 .2 .2 1"/>
    <material name="white" rgba="1 1 1 1"/>
    <material name="red" rgba="1 0.072272 0.039546 1"/>
    <material name="gray" rgba="0.863156 0.863156 0.863157 1"/>
    <material name="button_green" rgba="0.102241 0.571125 0.102242 1"/>
    <material name="button_red" rgba="0.520996 0.008023 0.013702 1"/>
    <material name="button_blue" rgba="0.024157 0.445201 0.737911 1"/>

    <mesh file="link0_0.obj"/>
    <mesh file="link0_1.obj"/>
    <mesh file="link0_2.obj"/>
    <mesh file="link0_3.obj"/>
    <mesh file="link0_4.obj"/>
    <mesh file="link0_5.obj"/>
    <mesh file="link0_6.obj"/>
    <mesh file="link1.obj"/>
    <mesh file="link2.obj"/>
    <mesh file="link3_0.obj"/>
    <mesh file="link3_1.obj"/>
    <mesh file="link4_0.obj"/>
    <mesh file="link4_1.obj"/>
    <mesh file="link5_0.obj"/>
    <mesh file="link5_1.obj"/>
    <mesh file="link5_2.obj"/>
    <mesh file="link6_0.obj"/>
    <mesh file="link6_1.obj"/>
    <mesh file="link6_2.obj"/>
    <mesh file="link6_3.obj"/>
    <mesh file="link6_4.obj"/>
    <mesh file="link6_5.obj"/>
    <mesh file="link6_6.obj"/>
    <mesh file="link6_7.obj"/>
    <mesh file="link7_0.obj"/>
    <mesh file="link7_1.obj"/>
    <mesh file="link7_2.obj"/>
    <mesh file="link7_3.obj"/>

    <mesh name="link0_coll" file="link0.stl"/>
    <mesh name="link1_coll" file="link1.stl"/>
    <mesh name="link2_coll" file="link2.stl"/>
    <mesh name="link3_coll" file="link3.stl"/>
    <mesh name="link4_coll" file="link4.stl"/>
    <mesh name="link5_coll" file="link5.stl"/>
    <mesh name="link6_coll" file="link6.stl"/>
    <mesh name="link7_coll" file="link7.stl"/>

    <mesh name="link2_fancy" file="../skin_meshes/skin_link2_fancy.stl"/>
    <mesh name="link3_fancy" file="../skin_meshes/skin_link3_fancy.stl"/>
    <mesh name="link5_fancy" file="../skin_meshes/skin_link5_fancy.stl"/>
    <mesh name="link6_fancy" file="../skin_meshes/skin_link6_fancy.stl"/>

    <model file="robotiq_2f85_v4/2f85.xml" name="robotiq_gripper" />
  </asset>

  <worldbody>
    <body childclass="fr3">
      <body name="fr3_link0">
        <geom mesh="link0_0" material="black" class="visual"/>
        <geom mesh="link0_1" material="white" class="visual"/>
        <geom mesh="link0_2" material="white" class="visual"/>
        <geom mesh="link0_3" material="white" class="visual"/>
        <geom mesh="link0_4" material="white" class="visual"/>
        <geom mesh="link0_5" material="red" class="visual"/>
        <geom mesh="link0_6" material="black" class="visual"/>
        <geom name="fr3_link0_collision" mesh="link0_coll" class="collision"/>
        <body name="fr3_link1" pos="0 0 0.333">
          <inertial pos="4.128e-07 -0.0181251 -0.0386036" quat="0.999901 0.0021545 0.00429041 0.0132325" mass="2.92747"
            diaginertia="0.0186043 0.0181194 0.00538716"/>
          <joint name="fr3_joint1" axis="0 0 1" range="-2.7437 2.7437" actuatorfrcrange="-87 87"/>
          <geom name="fr3_link1_collision" class="collision" mesh="link1_coll"/>
          <geom material="white" mesh="link1" class="visual"/>
          <body name="fr3_link2" quat="1 -1 0 0">
            <inertial pos="0.00318289 -0.0743222 0.00881461" quat="0.356855 0.680818 -0.434812 0.469126" mass="2.93554"
              diaginertia="0.0299291 0.0299291 0.0299291"/>
            <joint name="fr3_joint2" axis="0 0 1" range="-1.7837 1.7837" actuatorfrcrange="-87 87"/>
            <geom material="white" mesh="link2" class="visual"/>
            <geom name="fr3_link2_collision" class="collision" mesh="link2_coll"/>

            <body name="link2_skin" quat="0.70714084 0.70707272 0 0">
              <geom class="skin" type="mesh" mesh="link2_fancy"/>
              <body name="link2_sensor_0" pos="-0.048 0.113 -0.006" quat="0.31456781 0.34743113 -0.65483748 -0.59289677">
                <site name="link2_sensor_0_site" class="skin_sensor_site"/>
                <camera name="link2_sensor_0" mode="fixed" pos="0 0 0" quat="0 1 0 0" fovy="45.0" resolution="8 8"/>
              </body>
              <body name="link2_sensor_1" pos="0.032 0.053 0.147" quat="0.22515889 0.21529195 0.6567029 0.68679993">
                <site name="link2_sensor_1_site" class="skin_sensor_site"/>
                <camera name="link2_sensor_1" mode="fixed" pos="0 0 0" quat="0 1 0 0" fovy="45.0" resolution="8 8"/>
              </body>
              <body name="link2_sensor_2" pos="-0.046 0.04 0.162" quat="0.29099594 0.28472143 -0.63877727 -0.65285424">
                <site name="link2_sensor_2_site" class="skin_sensor_site"/>
                <camera name="link2_sensor_2" mode="fixed" pos="0 0 0" quat="0 1 0 0" fovy="45.0" resolution="8 8"/>
              </body>
              <body name="link2_sensor_3" pos="0.05 0.11 0.007" quat="0.32760406 0.30919657 0.61279312 0.64927472">
                <site name="link2_sensor_3_site" class="skin_sensor_site"/>
                <camera name="link2_sensor_3" mode="fixed" pos="0 0 0" quat="0 1 0 0" fovy="45.0" resolution="8 8"/>
              </body>
              <body name="link2_sensor_4" pos="0.004 0.074 0.093" quat="0.038944856 0.024065243 0.52511671 0.84979798">
                <site name="link2_sensor_4_site" class="skin_sensor_site"/>
                <camera name="link2_sensor_4" mode="fixed" pos="0 0 0" quat="0 1 0 0" fovy="45.0" resolution="8 8"/>
              </body>
              <body name="link2_sensor_5" pos="0.001 0.117 0.045" quat="0.035635764 0.016537803 0.42063193 0.90638037">
                <site name="link2_sensor_5_site" class="skin_sensor_site"/>
                <camera name="link2_sensor_5" mode="fixed" pos="0 0 0" quat="0 1 0 0" fovy="45.0" resolution="8 8"/>
              </body>
              <body name="link2_sensor_6" pos="0.019 0.111 -0.046" quat="-0.094688397 -0.26880407 -0.90431475 -0.31779444">
                <site name="link2_sensor_6_site" class="skin_sensor_site"/>
                <camera name="link2_sensor_6" mode="fixed" pos="0 0 0" quat="0 1 0 0" fovy="45.0" resolution="8 8"/>
              </body>
            </body>

            <body name="fr3_link3" pos="0 -0.316 0" quat="1 1 0 0">
              <inertial pos="0.0407016 -0.00482006 -0.0289731" quat="0.950032 -0.148357 0.229935 0.150201" mass="2.2449"
                diaginertia="0.0140109 0.0140109 0.0140109"/>
              <joint name="fr3_joint3" axis="0 0 1" range="-2.9007 2.9007" actuatorfrcrange="-87 87"/>
              <geom mesh="link3_0" material="white" class="visual"/>
              <geom mesh="link3_1" material="black" class="visual"/>
              <geom name="fr3_link3_collision" class="collision" mesh="link3_coll"/>

              <body name="link3_skin">
                <geom class="skin" type="mesh" mesh="link3_fancy"/>
                <body name="link3_sensor_0" pos="0.008 0.051 -0.043" quat="0.022862703 0.019101183 -0.64086858 -0.76707229">
                  <site name="link3_sensor_0_site" class="skin_sensor_site"/>
                  <camera name="link3_sensor_0" mode="fixed" pos="0 0 0" quat="0 1 0 0" fovy="45.0" resolution="8 8"/>
                </body>
                <body name="link3_sensor_1" pos="0.097 0.113 -0.015" quat="0.070738357 0.086270041 0.76845394 0.63010483">
                  <site name="link3_sensor_1_site" class="skin_sensor_site"/>
                  <camera name="link3_sensor_1" mode="fixed" pos="0 0 0" quat="0 1 0 0" fovy="45.0" resolution="8 8"/>
                </body>
                <body name="link3_sensor_2" pos="-0.041 -0.037 -0.071" quat="0.6947271 0.60503398 -0.25544775 -0.29331654">
                  <site name="link3_sensor_2_site" class="skin_sensor_site"/>
                  <camera name="link3_sensor_2" mode="fixed" pos="0 0 0" quat="0 1 0 0" fovy="45.0" resolution="8 8"/>
                </body>
                <body name="link3_sensor_3" pos="0.107 0.106 0.026" quat="0.17617356 0.11910967 0.54728316 0.8094794">
                  <site name="link3_sensor_3_site" class="skin_sensor_site"/>
                  <camera name="link3_sensor_3" mode="fixed" pos="0 0 0" quat="0 1 0 0" fovy="45.0" resolution="8 8"/>
                </body>
                <body name="link3_sensor_4" pos="0.067 0.106 0.031" quat="0.11682534 0.070346555 -0.51103129 -0.84867557">
                  <site name="link3_sensor_4_site" class="skin_sensor_site"/>
                  <camera name="link3_sensor_4" mode="fixed" pos="0 0 0" quat="0 1 0 0" fovy="45.0" resolution="8 8"/>
                </body>
                <body name="link3_sensor_5" pos="0.057 0.108 -0.019" quat="0.11890805 0.15583407 -0.7795726 -0.5948472">
                  <site name="link3_sensor_5_site" class="skin_sensor_site"/>
                  <camera name="link3_sensor_5" mode="fixed" pos="0 0 0" quat="0 1 0 0" fovy="45.0" resolution="8 8"/>
                </body>
                <body name="link3_sensor_6" pos="-0.05 0.023 -0.063" quat="0.39264794 0.33954565 -0.55907361 -0.64650835">
                  <site name="link3_sensor_6_site" class="skin_sensor_site"/>
                  <camera name="link3_sensor_6" mode="fixed" pos="0 0 0" quat="0 1 0 0" fovy="45.0" resolution="8 8"/>
                </body>
                <body name="link3_sensor_7" pos="0.085 0.086 -0.05" quat="0.014105077 0.091285061 0.98370779 0.15423057">
                  <site name="link3_sensor_7_site" class="skin_sensor_site"/>
                  <camera name="link3_sensor_7" mode="fixed" pos="0 0 0" quat="0 1 0 0" fovy="45.0" resolution="8 8"/>
                </body>
              </body>

              <body name="fr3_link4" pos="0.0825 0 0" quat="1 1 0 0">
                <inertial pos="-0.0459101 0.0630493 -0.00851879" quat="0.23761 0.892458 -0.00078702 0.383484"
                  mass="2.6156" diaginertia="0.0206104 0.0206104 0.0206104"/>
                <joint name="fr3_joint4" axis="0 0 1" range="-3.0421 -0.1518" actuatorfrcrange="-87 87"/>
                <geom mesh="link4_0" material="white" class="visual"/>
                <geom mesh="link4_1" material="black" class="visual"/>
                <geom name="fr3_link4_collision" class="collision" mesh="link4_coll"/>
                <body name="fr3_link5" pos="-0.0825 0.384 0" quat="1 -1 0 0">
                  <inertial pos="-0.00160396 0.0292536 -0.0972966" quat="0.922285 0.098826 0.0982562 -0.360514"
                    mass="2.32712" diaginertia="0.0182879 0.0182879 0.0182879"/>
                  <joint name="fr3_joint5" axis="0 0 1" range="-2.8065 2.8065" actuatorfrcrange="-12 12"/>
                  <geom mesh="link5_0" material="white" class="visual"/>
                  <geom mesh="link5_1" material="white" class="visual"/>
                  <geom mesh="link5_2" material="black" class="visual"/>
                  <geom name="fr3_link5_collision" class="collision" mesh="link5_coll"/>

                  <body name="link5_skin">
                    <geom class="skin" type="mesh" mesh="link5_fancy"/>
                    <body name="link5_sensor_0" pos="-0 0.096 -0.184" quat="-0.0057689103 -0.007550393 0.80740265 0.58992429">
                      <site name="link5_sensor_0_site" class="skin_sensor_site"/>
                      <camera name="link5_sensor_0" mode="fixed" pos="0 0 0" quat="0 1 0 0" fovy="45.0" resolution="8 8"/>
                    </body>
                    <body name="link5_sensor_1" pos="-0.007 0.127 -0.038" quat="0.015398607 0.022175374 -0.81676084 -0.5763444">
                      <site name="link5_sensor_1_site" class="skin_sensor_site"/>
                      <camera name="link5_sensor_1" mode="fixed" pos="0 0 0" quat="0 1 0 0" fovy="45.0" resolution="8 8"/>
                    </body>
                    <body name="link5_sensor_2" pos="-0.016 0.104 -0.138" quat="0.075152014 0.090355338 -0.76349603 -0.63502905">
                      <site name="link5_sensor_2_site" class="skin_sensor_site"/>
                      <camera name="link5_sensor_2" mode="fixed" pos="0 0 0" quat="0 1 0 0" fovy="45.0" resolution="8 8"/>
                    </body>
                    <body name="link5_sensor_3" pos="-0.007 0.133 0.023" quat="0.042801802 0.02731399 -0.53725329 -0.84189123">
                      <site name="link5_sensor_3_site" class="skin_sensor_site"/>
                      <camera name="link5_sensor_3" mode="fixed" pos="0 0 0" quat="0 1 0 0" fovy="45.0" resolution="8 8"/>
                    </body>
                    <body name="link5_sensor_4" pos="0.026 0.13 -0.013" quat="0.12395629 0.14994548 0.75601242 0.62497713">
                      <site name="link5_sensor_4_site" class="skin_sensor_site"/>
                      <camera name="link5_sensor_4" mode="fixed" pos="0 0 0" quat="0 1 0 0" fovy="45.0" resolution="8 8"/>
                    </body>
                    <body name="link5_sensor_5" pos="-0.004 0.115 -0.089" quat="0.015654307 0.018844469 -0.76364252 -0.64517434">
                      <site name="link5_sensor_5_site" class="skin_sensor_site"/>
                      <camera name="link5_sensor_5" mode="fixed" pos="0 0 0" quat="0 1 0 0" fovy="45.0" resolution="8 8"/>
                    </body>
                  </body>

                  <body name="fr3_link6" quat="1 1 0 0">
                    <inertial pos="0.0597131 -0.0410295 -0.0101693" quat="0.593933 0.525442 0.520644 0.316361"
                      mass="1.81704" diaginertia="0.00483538 0.00483538 0.00483538"/>
                    <joint name="fr3_joint6" axis="0 0 1" range="0.5445 4.5169" actuatorfrcrange="-12 12"/>
                    <geom mesh="link6_0" material="button_green" class="visual"/>
                    <geom mesh="link6_1" material="white" class="visual"/>
                    <geom mesh="link6_2" material="white" class="visual"/>
                    <geom mesh="link6_3" material="gray" class="visual"/>
                    <geom mesh="link6_4" material="button_red" class="visual"/>
                    <geom mesh="link6_5" material="white" class="visual"/>
                    <geom mesh="link6_6" material="black" class="visual"/>
                    <geom mesh="link6_7" material="button_blue" class="visual"/>
                    <geom name="fr3_link6_collision" class="collision" mesh="link6_coll"/>

                    <body name="link6_skin" quat="0.70710678 -0.70710678 0 0">
                      <geom class="skin" type="mesh" mesh="link6_fancy"/>
                      <body name="link6_sensor_0" pos="0.117 -0.045 -0.004" quat="0.68179467 0.68947638 0.17385061 0.17191368">
                        <site name="link6_sensor_0_site" class="skin_sensor_site"/>
                        <camera name="link6_sensor_0" mode="fixed" pos="0 0 0" quat="0 1 0 0" fovy="45.0" resolution="8 8"/>
                      </body>
                      <body name="link6_sensor_1" pos="0.133 -0.025 0.039" quat="0.63763575 0.56548474 0.34709078 0.3913766">
                        <site name="link6_sensor_1_site" class="skin_sensor_site"/>
                        <camera name="link6_sensor_1" mode="fixed" pos="0 0 0" quat="0 1 0 0" fovy="45.0" resolution="8 8"/>
                      </body>
                      <body name="link6_sensor_2" pos="0.14 -0.002 0.03" quat="0.54754302 0.50348124 0.45239086 0.4919815">
                        <site name="link6_sensor_2_site" class="skin_sensor_site"/>
                        <camera name="link6_sensor_2" mode="fixed" pos="0 0 0" quat="0 1 0 0" fovy="45.0" resolution="8 8"/>
                      </body>
                      <body name="link6_sensor_3" pos="0.113 0.047 0.002" quat="0.1728753 0.17534837 0.69018443 0.68045024">
                        <site name="link6_sensor_3_site" class="skin_sensor_site"/>
                        <camera name="link6_sensor_3" mode="fixed" pos="0 0 0" quat="0 1 0 0" fovy="45.0" resolution="8 8"/>
                      </body>
                      <body name="link6_sensor_4" pos="0.132 0.029 0.018" quat="0.37454461 0.36064915 0.59248504 0.61531292">
                        <site name="link6_sensor_4_site" class="skin_sensor_site"/>
                        <camera name="link6_sensor_4" mode="fixed" pos="0 0 0" quat="0 1 0 0" fovy="45.0" resolution="8 8"/>
                      </body>
                      <body name="link6_sensor_5" pos="0.141 -0.001 -0.002" quat="0.52187055 0.5272229 0.47658972 0.47175139">
                        <site name="link6_sensor_5_site" class="skin_sensor_site"/>
                        <camera name="link6_sensor_5" mode="fixed" pos="0 0 0" quat="0 1 0 0" fovy="45.0" resolution="8 8"/>
                      </body>
                      <body name="link6_sensor_6" pos="0.13 -0.033 0.015" quat="0.64798813 0.62896251 0.29918256 0.3082326">
                        <site name="link6_sensor_6_site" class="skin_sensor_site"/>
                        <camera name="link6_sensor_6" mode="fixed" pos="0 0 0" quat="0 1 0 0" fovy="45.0" resolution="8 8"/>
                      </body>
                      <body name="link6_sensor_7" pos="0.087 0.051 0.036" quat="0.034051073 0.031342358 -0.67651074 -0.73497715">
                        <site name="link6_sensor_7_site" class="skin_sensor_site"/>
                        <camera name="link6_sensor_7" mode="fixed" pos="0 0 0" quat="0 1 0 0" fovy="45.0" resolution="8 8"/>
                      </body>
                    </body>

                    <body name="fr3_link7" pos="0.088 0 0" quat="1 1 0 0">
                      <inertial pos="0.00452258 0.00862619 -0.0161633" quat="0.120255 0.394761 -0.799132 0.437139"
                        mass="0.627143" diaginertia="3.076e-07 3.076e-07 3.076e-07"/>
                      <joint name="fr3_joint7" axis="0 0 1" range="-3.0159 3.0159" actuatorfrcrange="-12 12"/>
                      <geom mesh="link7_0" material="black" class="visual"/>
                      <geom mesh="link7_1" material="white" class="visual"/>
                      <geom mesh="link7_2" material="white" class="visual"/>
                      <geom mesh="link7_3" material="black" class="visual"/>
                      <geom name="fr3_link7_collision" class="collision" mesh="link7_coll"/>
                      <site name="attachment_site" pos="0 0 0.107"/>
                      <body name="wrist_cam_body" pos="0.05 0 0.107">
                        <camera name="wrist_cam" fovy="90" xyaxes="0 1 0 1 0 0" />
                      </body>
                      <frame pos="0 0 0.107" quat="0.7071068 0 0 0.7071068">
                        <attach model="robotiq_gripper" body="base" prefix="gripper/"/>
                      </frame>
                    </body>
                  </body>
                </body>
              </body>
            </body>
          </body>
        </body>
      </body>
    </body>
  </worldbody>

  <actuator>
    <position class="fr3" name="fr3_joint1" joint="fr3_joint1" kp="4500" kv="450"/>
    <position class="fr3" name="fr3_joint2" joint="fr3_joint2" kp="4500" kv="450"/>
    <position class="fr3" name="fr3_joint3" joint="fr3_joint3" kp="3500" kv="350"/>
    <position class="fr3" name="fr3_joint4" joint="fr3_joint4" kp="3500" kv="350"/>
    <position class="fr3" name="fr3_joint5" joint="fr3_joint5" kp="2000" kv="200"/>
    <position class="fr3" name="fr3_joint6" joint="fr3_joint6" kp="2000" kv="200"/>
    <position class="fr3" name="fr3_joint7" joint="fr3_joint7" kp="2000" kv="200"/>
  </actuator>
</mujoco>
