<?xml version="1.0" ?>
<mujoco model="fr3_skin">
  <compiler angle="radian" autolimits="true" meshdir="/home/jaydv/code/proximity_learning/assets/.cache/gentact_ros_tools/meshes" balanceinertia="true" boundmass="1e-6" boundinertia="1e-9"/>
  <option integrator="implicitfast" timestep="0.002">
    <flag gravity="disable"/>
  </option>
  <default>
    <geom contype="1" conaffinity="1" rgba="0.75 0.75 0.78 1"/>
    <default class="skin">
      <geom rgba="0.25 0.55 0.85 0.35" contype="0" conaffinity="0"/>
    </default>
  </default>
  <asset>
    <texture name="grid" type="2d" builtin="checker" rgb1="0.3 0.3 0.35" rgb2="0.2 0.2 0.25" width="300" height="300"/>
    <material name="grid" texture="grid" texrepeat="5 5" reflectance="0.1"/>
    <mesh name="link0" file="/home/jaydv/code/molmo/fr3_skin_mujoco/.mesh_cache/robot_arms/fr3/visual/link0.obj"/>
    <mesh name="link1" file="/home/jaydv/code/molmo/fr3_skin_mujoco/.mesh_cache/robot_arms/fr3/visual/link1.obj"/>
    <mesh name="link2" file="/home/jaydv/code/molmo/fr3_skin_mujoco/.mesh_cache/robot_arms/fr3/visual/link2.obj"/>
    <mesh name="link2_fancy" file="skin/self-cap/link2_fancy.stl"/>
    <mesh name="link3" file="/home/jaydv/code/molmo/fr3_skin_mujoco/.mesh_cache/robot_arms/fr3/visual/link3.obj"/>
    <mesh name="link3_fancy" file="skin/self-cap/link3_fancy.stl"/>
    <mesh name="link4" file="/home/jaydv/code/molmo/fr3_skin_mujoco/.mesh_cache/robot_arms/fr3/visual/link4.obj"/>
    <mesh name="link5" file="/home/jaydv/code/molmo/fr3_skin_mujoco/.mesh_cache/robot_arms/fr3/visual/link5.obj"/>
    <mesh name="link5_fancy" file="skin/self-cap/link5_fancy.stl"/>
    <mesh name="link6" file="/home/jaydv/code/molmo/fr3_skin_mujoco/.mesh_cache/robot_arms/fr3/visual/link6.obj"/>
    <mesh name="link6_fancy" file="skin/self-cap/link6_fancy.stl"/>
    <mesh name="link7" file="/home/jaydv/code/molmo/fr3_skin_mujoco/.mesh_cache/robot_arms/fr3/visual/link7.obj"/>
  </asset>
  <worldbody>
    <light pos="0 0 3" dir="0 0 -1" diffuse="0.8 0.8 0.8"/>
    <geom name="floor" type="plane" size="2 2 0.05" material="grid" pos="0 0 0"/>
    <body name="base" pos="0 0 0" quat="1 0 0 0">
      <body name="fr3_link0" pos="0 0 0" quat="1 0 0 0">
        <inertial pos="-0.0172 0.0004 0.0745" mass="2.3966" fullinertia="0.009 0.0115 0.0085 0.0 0.002 0.0"/>
        <geom type="mesh" mesh="link0"/>
        <body name="fr3_link1" pos="0 0 0.333" quat="1 0 0 0">
          <joint name="fr3_joint1" type="hinge" axis="0 0 1" range="-2.7437 2.7437" damping="0.003"/>
          <inertial pos="4.128e-07 -0.018125132 -0.038603597" mass="2.9274653" fullinertia="0.023927316485107913 0.0224821613275756 0.006350098258530016 1.3317903455714081e-05 -0.00011404774918616684 -0.0019950320628240115"/>
          <geom type="mesh" mesh="link1"/>
          <body name="fr3_link2" pos="0 0 0" quat="0.70710678 -0.70710678 0 0">
            <joint name="fr3_joint2" type="hinge" axis="0 0 1" range="-1.7837 1.7837" damping="0.003"/>
            <inertial pos="0.0031828864 -0.074322164 0.0088146084" mass="2.935537" fullinertia="0.041938946257609425 0.02514514885014724 0.06170214472888839 0.00020257331521090626 0.004077784227179924 -0.0042252158006570156"/>
            <geom type="mesh" mesh="link2"/>
            <body name="link2_skin" pos="0 0 0" quat="0.70714084 0.70707272 0 0">
              <geom type="mesh" mesh="link2_fancy" class="skin"/>
              <body name="link2_sensor_0" pos="-0.048 0.113 -0.006" quat="0.31456781 0.34743113 -0.65483748 -0.59289677">
                <site name="link2_sensor_0_site" type="sphere" size="0.004" rgba="1 0.2 0.2 1"/>
                <camera name="link2_sensor_0" mode="fixed" pos="0 0 0" quat="0 1 0 0" fovy="45.0" resolution="8 8"/>
              </body>
              <body name="link2_sensor_1" pos="0.032 0.053 0.147" quat="0.22515889 0.21529195 0.6567029 0.68679993">
                <site name="link2_sensor_1_site" type="sphere" size="0.004" rgba="1 0.2 0.2 1"/>
                <camera name="link2_sensor_1" mode="fixed" pos="0 0 0" quat="0 1 0 0" fovy="45.0" resolution="8 8"/>
              </body>
              <body name="link2_sensor_2" pos="-0.046 0.04 0.162" quat="0.29099594 0.28472143 -0.63877727 -0.65285424">
                <site name="link2_sensor_2_site" type="sphere" size="0.004" rgba="1 0.2 0.2 1"/>
                <camera name="link2_sensor_2" mode="fixed" pos="0 0 0" quat="0 1 0 0" fovy="45.0" resolution="8 8"/>
              </body>
              <body name="link2_sensor_3" pos="0.05 0.11 0.007" quat="0.32760406 0.30919657 0.61279312 0.64927472">
                <site name="link2_sensor_3_site" type="sphere" size="0.004" rgba="1 0.2 0.2 1"/>
                <camera name="link2_sensor_3" mode="fixed" pos="0 0 0" quat="0 1 0 0" fovy="45.0" resolution="8 8"/>
              </body>
              <body name="link2_sensor_4" pos="0.004 0.074 0.093" quat="0.038944856 0.024065243 0.52511671 0.84979798">
                <site name="link2_sensor_4_site" type="sphere" size="0.004" rgba="1 0.2 0.2 1"/>
                <camera name="link2_sensor_4" mode="fixed" pos="0 0 0" quat="0 1 0 0" fovy="45.0" resolution="8 8"/>
              </body>
              <body name="link2_sensor_5" pos="0.001 0.117 0.045" quat="0.035635764 0.016537803 0.42063193 0.90638037">
                <site name="link2_sensor_5_site" type="sphere" size="0.004" rgba="1 0.2 0.2 1"/>
                <camera name="link2_sensor_5" mode="fixed" pos="0 0 0" quat="0 1 0 0" fovy="45.0" resolution="8 8"/>
              </body>
              <body name="link2_sensor_6" pos="0.019 0.111 -0.046" quat="-0.094688397 -0.26880407 -0.90431475 -0.31779444">
                <site name="link2_sensor_6_site" type="sphere" size="0.004" rgba="1 0.2 0.2 1"/>
                <camera name="link2_sensor_6" mode="fixed" pos="0 0 0" quat="0 1 0 0" fovy="45.0" resolution="8 8"/>
              </body>
            </body>
            <body name="fr3_link3" pos="0 -0.316 0" quat="0.70710678 0.70710678 0 0">
              <joint name="fr3_joint3" type="hinge" axis="0 0 1" range="-2.9007 2.9007" damping="0.003"/>
              <inertial pos="0.040701569 -0.0048200565 -0.028973082" mass="2.2449014" fullinertia="0.02410142547240885 0.01974053266708178 0.019044494482244823 0.002404694559042109 -0.002856269270114313 -0.002104212683891874"/>
              <geom type="mesh" mesh="link3"/>
              <body name="link3_skin" pos="0 0 0" quat="1 0 0 0">
                <geom type="mesh" mesh="link3_fancy" class="skin"/>
                <body name="link3_sensor_0" pos="0.008 0.051 -0.043" quat="0.022862703 0.019101183 -0.64086858 -0.76707229">
                  <site name="link3_sensor_0_site" type="sphere" size="0.004" rgba="1 0.2 0.2 1"/>
                  <camera name="link3_sensor_0" mode="fixed" pos="0 0 0" quat="0 1 0 0" fovy="45.0" resolution="8 8"/>
                </body>
                <body name="link3_sensor_1" pos="0.097 0.113 -0.015" quat="0.070738357 0.086270041 0.76845394 0.63010483">
                  <site name="link3_sensor_1_site" type="sphere" size="0.004" rgba="1 0.2 0.2 1"/>
                  <camera name="link3_sensor_1" mode="fixed" pos="0 0 0" quat="0 1 0 0" fovy="45.0" resolution="8 8"/>
                </body>
                <body name="link3_sensor_2" pos="-0.041 -0.037 -0.071" quat="0.6947271 0.60503398 -0.25544775 -0.29331654">
                  <site name="link3_sensor_2_site" type="sphere" size="0.004" rgba="1 0.2 0.2 1"/>
                  <camera name="link3_sensor_2" mode="fixed" pos="0 0 0" quat="0 1 0 0" fovy="45.0" resolution="8 8"/>
                </body>
                <body name="link3_sensor_3" pos="0.107 0.106 0.026" quat="0.17617356 0.11910967 0.54728316 0.8094794">
                  <site name="link3_sensor_3_site" type="sphere" size="0.004" rgba="1 0.2 0.2 1"/>
                  <camera name="link3_sensor_3" mode="fixed" pos="0 0 0" quat="0 1 0 0" fovy="45.0" resolution="8 8"/>
                </body>
                <body name="link3_sensor_4" pos="0.067 0.106 0.031" quat="0.11682534 0.070346555 -0.51103129 -0.84867557">
                  <site name="link3_sensor_4_site" type="sphere" size="0.004" rgba="1 0.2 0.2 1"/>
                  <camera name="link3_sensor_4" mode="fixed" pos="0 0 0" quat="0 1 0 0" fovy="45.0" resolution="8 8"/>
                </body>
                <body name="link3_sensor_5" pos="0.057 0.108 -0.019" quat="0.11890805 0.15583407 -0.7795726 -0.5948472">
                  <site name="link3_sensor_5_site" type="sphere" size="0.004" rgba="1 0.2 0.2 1"/>
                  <camera name="link3_sensor_5" mode="fixed" pos="0 0 0" quat="0 1 0 0" fovy="45.0" resolution="8 8"/>
                </body>
                <body name="link3_sensor_6" pos="-0.05 0.023 -0.063" quat="0.39264794 0.33954565 -0.55907361 -0.64650835">
                  <site name="link3_sensor_6_site" type="sphere" size="0.004" rgba="1 0.2 0.2 1"/>
                  <camera name="link3_sensor_6" mode="fixed" pos="0 0 0" quat="0 1 0 0" fovy="45.0" resolution="8 8"/>
                </body>
                <body name="link3_sensor_7" pos="0.085 0.086 -0.05" quat="0.014105077 0.091285061 0.98370779 0.15423057">
                  <site name="link3_sensor_7_site" type="sphere" size="0.004" rgba="1 0.2 0.2 1"/>
                  <camera name="link3_sensor_7" mode="fixed" pos="0 0 0" quat="0 1 0 0" fovy="45.0" resolution="8 8"/>
                </body>
              </body>
              <body name="fr3_link4" pos="0.0825 0 0" quat="0.70710678 0.70710678 0 0">
                <joint name="fr3_joint4" type="hinge" axis="0 0 1" range="-3.0421 -0.1518" damping="0.003"/>
                <inertial pos="-0.045910096 0.063049296 -0.0085187868" mass="2.6155956" fullinertia="0.03452998321913202 0.028881621933049058 0.04125471171146641 0.01322552265982813 0.01015142998484113 -0.0009762833870704552"/>
                <geom type="mesh" mesh="link4"/>
                <body name="fr3_link5" pos="-0.0825 0.384 0" quat="0.70710678 -0.70710678 0 0">
                  <joint name="fr3_joint5" type="hinge" axis="0 0 1" range="-2.8065 2.8065" damping="0.003"/>
                  <inertial pos="-0.0016039605 0.029253626 -0.097296599" mass="2.3271208" fullinertia="0.051610278463662895 0.04787729713371481 0.016423625579357254 -0.005715173387783472 -0.0035673167625872135 0.010673985108535986"/>
                  <geom type="mesh" mesh="link5"/>
                  <body name="link5_skin" pos="0 0 0" quat="1 0 0 0">
                    <geom type="mesh" mesh="link5_fancy" class="skin"/>
                    <body name="link5_sensor_0" pos="-0 0.096 -0.184" quat="-0.0057689103 -0.007550393 0.80740265 0.58992429">
                      <site name="link5_sensor_0_site" type="sphere" size="0.004" rgba="1 0.2 0.2 1"/>
                      <camera name="link5_sensor_0" mode="fixed" pos="0 0 0" quat="0 1 0 0" fovy="45.0" resolution="8 8"/>
                    </body>
                    <body name="link5_sensor_1" pos="-0.007 0.127 -0.038" quat="0.015398607 0.022175374 -0.81676084 -0.5763444">
                      <site name="link5_sensor_1_site" type="sphere" size="0.004" rgba="1 0.2 0.2 1"/>
                      <camera name="link5_sensor_1" mode="fixed" pos="0 0 0" quat="0 1 0 0" fovy="45.0" resolution="8 8"/>
                    </body>
                    <body name="link5_sensor_2" pos="-0.016 0.104 -0.138" quat="0.075152014 0.090355338 -0.76349603 -0.63502905">
                      <site name="link5_sensor_2_site" type="sphere" size="0.004" rgba="1 0.2 0.2 1"/>
                      <camera name="link5_sensor_2" mode="fixed" pos="0 0 0" quat="0 1 0 0" fovy="45.0" resolution="8 8"/>
                    </body>
                    <body name="link5_sensor_3" pos="-0.007 0.133 0.023" quat="0.042801802 0.02731399 -0.53725329 -0.84189123">
                      <site name="link5_sensor_3_site" type="sphere" size="0.004" rgba="1 0.2 0.2 1"/>
                      <camera name="link5_sensor_3" mode="fixed" pos="0 0 0" quat="0 1 0 0" fovy="45.0" resolution="8 8"/>
                    </body>
                    <body name="link5_sensor_4" pos="0.026 0.13 -0.013" quat="0.12395629 0.14994548 0.75601242 0.62497713">
                      <site name="link5_sensor_4_site" type="sphere" size="0.004" rgba="1 0.2 0.2 1"/>
                      <camera name="link5_sensor_4" mode="fixed" pos="0 0 0" quat="0 1 0 0" fovy="45.0" resolution="8 8"/>
                    </body>
                    <body name="link5_sensor_5" pos="-0.004 0.115 -0.089" quat="0.015654307 0.018844469 -0.76364252 -0.64517434">
                      <site name="link5_sensor_5_site" type="sphere" size="0.004" rgba="1 0.2 0.2 1"/>
                      <camera name="link5_sensor_5" mode="fixed" pos="0 0 0" quat="0 1 0 0" fovy="45.0" resolution="8 8"/>
                    </body>
                  </body>
                  <body name="fr3_link6" pos="0 0 0" quat="0.70710678 0.70710678 0 0">
                    <joint name="fr3_joint6" type="hinge" axis="0 0 1" range="0.5445 4.5169" damping="0.003"/>
                    <inertial pos="0.059713122 -0.041029467 -0.010169273" mass="1.8170377" fullinertia="0.005412333594383447 0.014058329545509979 0.016080817924212554 0.006193456360285834 0.0014219289306117652 -0.0013140753741120031"/>
                    <geom type="mesh" mesh="link6"/>
                    <body name="link6_skin" pos="0 0 0" quat="0.70710678 -0.70710678 0 0">
                      <geom type="mesh" mesh="link6_fancy" class="skin"/>
                      <body name="link6_sensor_0" pos="0.117 -0.045 -0.004" quat="0.68179467 0.68947638 0.17385061 0.17191368">
                        <site name="link6_sensor_0_site" type="sphere" size="0.004" rgba="1 0.2 0.2 1"/>
                        <camera name="link6_sensor_0" mode="fixed" pos="0 0 0" quat="0 1 0 0" fovy="45.0" resolution="8 8"/>
                      </body>
                      <body name="link6_sensor_1" pos="0.133 -0.025 0.039" quat="0.63763575 0.56548474 0.34709078 0.3913766">
                        <site name="link6_sensor_1_site" type="sphere" size="0.004" rgba="1 0.2 0.2 1"/>
                        <camera name="link6_sensor_1" mode="fixed" pos="0 0 0" quat="0 1 0 0" fovy="45.0" resolution="8 8"/>
                      </body>
                      <body name="link6_sensor_2" pos="0.14 -0.002 0.03" quat="0.54754302 0.50348124 0.45239086 0.4919815">
                        <site name="link6_sensor_2_site" type="sphere" size="0.004" rgba="1 0.2 0.2 1"/>
                        <camera name="link6_sensor_2" mode="fixed" pos="0 0 0" quat="0 1 0 0" fovy="45.0" resolution="8 8"/>
                      </body>
                      <body name="link6_sensor_3" pos="0.113 0.047 0.002" quat="0.1728753 0.17534837 0.69018443 0.68045024">
                        <site name="link6_sensor_3_site" type="sphere" size="0.004" rgba="1 0.2 0.2 1"/>
                        <camera name="link6_sensor_3" mode="fixed" pos="0 0 0" quat="0 1 0 0" fovy="45.0" resolution="8 8"/>
                      </body>
                      <body name="link6_sensor_4" pos="0.132 0.029 0.018" quat="0.37454461 0.36064915 0.59248504 0.61531292">
                        <site name="link6_sensor_4_site" type="sphere" size="0.004" rgba="1 0.2 0.2 1"/>
                        <camera name="link6_sensor_4" mode="fixed" pos="0 0 0" quat="0 1 0 0" fovy="45.0" resolution="8 8"/>
                      </body>
                      <body name="link6_sensor_5" pos="0.141 -0.001 -0.002" quat="0.52187055 0.5272229 0.47658972 0.47175139">
                        <site name="link6_sensor_5_site" type="sphere" size="0.004" rgba="1 0.2 0.2 1"/>
                        <camera name="link6_sensor_5" mode="fixed" pos="0 0 0" quat="0 1 0 0" fovy="45.0" resolution="8 8"/>
                      </body>
                      <body name="link6_sensor_6" pos="0.13 -0.033 0.015" quat="0.64798813 0.62896251 0.29918256 0.3082326">
                        <site name="link6_sensor_6_site" type="sphere" size="0.004" rgba="1 0.2 0.2 1"/>
                        <camera name="link6_sensor_6" mode="fixed" pos="0 0 0" quat="0 1 0 0" fovy="45.0" resolution="8 8"/>
                      </body>
                      <body name="link6_sensor_7" pos="0.087 0.051 0.036" quat="0.034051073 0.031342358 -0.67651074 -0.73497715">
                        <site name="link6_sensor_7_site" type="sphere" size="0.004" rgba="1 0.2 0.2 1"/>
                        <camera name="link6_sensor_7" mode="fixed" pos="0 0 0" quat="0 1 0 0" fovy="45.0" resolution="8 8"/>
                      </body>
                    </body>
                    <body name="fr3_link7" pos="0.088 0 0" quat="0.70710678 0.70710678 0 0">
                      <joint name="fr3_joint7" type="hinge" axis="0 0 1" range="-3.0159 3.0159" damping="0.003"/>
                      <inertial pos="0.0045225817 0.0086261921 -0.016163325" mass="0.62714329" fullinertia="0.00021092389150104718 0.00017718568002411474 5.993190599659971e-05 -2.433299114461931e-05 4.564480393778983e-05 8.744070223226438e-05"/>
                      <geom type="mesh" mesh="link7"/>
                    </body>
                  </body>
                </body>
              </body>
            </body>
          </body>
        </body>
      </body>
    </body>
  </worldbody>
  <keyframe>
    <key name="home" qpos="0 -0.785 0 -2.356 0 1.571 0.785"/>
  </keyframe>
  <visual>
    <map znear="0.005" zfar="10"/>
    <global offwidth="1280" offheight="960"/>
  </visual>
</mujoco>
